<?xml version="1.0" encoding="UTF-8"?>
<testng-results skipped="0" failed="2" ignored="0" total="2" passed="0">
  <reporter-output>
  </reporter-output>
  <suite name="Default suite" duration-ms="27880" started-at="2017-08-19T03:12:53Z" finished-at="2017-08-19T03:13:21Z">
    <groups>
    </groups>
    <test name="Default test" duration-ms="27880" started-at="2017-08-19T03:12:53Z" finished-at="2017-08-19T03:13:21Z">
      <class name="com.testingdocs.examples.testng.TakeScreenShotOnAssertFail">
        <test-method status="PASS" signature="setUp()[pri:0, instance:com.testingdocs.examples.testng.TakeScreenShotOnAssertFail@59f99ea]" name="setUp" is-config="true" duration-ms="8546" started-at="2017-08-19T08:42:54Z" finished-at="2017-08-19T08:43:02Z">
          <reporter-output>
          </reporter-output>
        </test-method> <!-- setUp -->
        <test-method status="FAIL" signature="sampleFailureTest()[pri:0, instance:com.testingdocs.examples.testng.TakeScreenShotOnAssertFail@59f99ea]" name="sampleFailureTest" duration-ms="5200" started-at="2017-08-19T08:43:02Z" finished-at="2017-08-19T08:43:07Z">
          <exception class="java.lang.AssertionError">
            <message>
              <![CDATA[Assert3 expected [Facebook – log in or sign up] but found [Bing]]]>
            </message>
            <full-stacktrace>
              <![CDATA[java.lang.AssertionError: Assert3 expected [Facebook – log in or sign up] but found [Bing]
	at org.testng.Assert.fail(Assert.java:93)
	at org.testng.Assert.failNotEquals(Assert.java:512)
	at org.testng.Assert.assertEqualsImpl(Assert.java:134)
	at org.testng.Assert.assertEquals(Assert.java:115)
	at org.testng.Assert.assertEquals(Assert.java:189)
	at org.testng.asserts.Assertion$10.doAssert(Assertion.java:193)
	at org.testng.asserts.Assertion.executeAssert(Assertion.java:30)
	at org.testng.asserts.Assertion.doAssert(Assertion.java:15)
	at org.testng.asserts.Assertion.assertEquals(Assertion.java:190)
	at com.testingdocs.examples.testng.TakeScreenShotOnAssertFail.sampleFailureTest(TakeScreenShotOnAssertFail.java:47)
	at sun.reflect.NativeMethodAccessorImpl.invoke0(Native Method)
	at sun.reflect.NativeMethodAccessorImpl.invoke(Unknown Source)
	at sun.reflect.DelegatingMethodAccessorImpl.invoke(Unknown Source)
	at java.lang.reflect.Method.invoke(Unknown Source)
	at org.testng.internal.MethodInvocationHelper.invokeMethod(MethodInvocationHelper.java:108)
	at org.testng.internal.Invoker.invokeMethod(Invoker.java:661)
	at org.testng.internal.Invoker.invokeTestMethod(Invoker.java:869)
	at org.testng.internal.Invoker.invokeTestMethods(Invoker.java:1193)
	at org.testng.internal.TestMethodWorker.invokeTestMethods(TestMethodWorker.java:126)
	at org.testng.internal.TestMethodWorker.run(TestMethodWorker.java:109)
	at org.testng.TestRunner.privateRun(TestRunner.java:744)
	at org.testng.TestRunner.run(TestRunner.java:602)
	at org.testng.SuiteRunner.runTest(SuiteRunner.java:380)
	at org.testng.SuiteRunner.runSequentially(SuiteRunner.java:375)
	at org.testng.SuiteRunner.privateRun(SuiteRunner.java:340)
	at org.testng.SuiteRunner.run(SuiteRunner.java:289)
	at org.testng.SuiteRunnerWorker.runSuite(SuiteRunnerWorker.java:52)
	at org.testng.SuiteRunnerWorker.run(SuiteRunnerWorker.java:86)
	at org.testng.TestNG.runSuitesSequentially(TestNG.java:1301)
	at org.testng.TestNG.runSuitesLocally(TestNG.java:1226)
	at org.testng.TestNG.runSuites(TestNG.java:1144)
	at org.testng.TestNG.run(TestNG.java:1115)
	at org.testng.remote.AbstractRemoteTestNG.run(AbstractRemoteTestNG.java:132)
	at org.testng.remote.RemoteTestNG.initAndRun(RemoteTestNG.java:230)
	at org.testng.remote.RemoteTestNG.main(RemoteTestNG.java:76)
]]>
            </full-stacktrace>
          </exception> <!-- java.lang.AssertionError -->
          <reporter-output>
          </reporter-output>
        </test-method> <!-- sampleFailureTest -->
        <test-method status="FAIL" signature="sampleTilteFailureTest()[pri:0, instance:com.testingdocs.examples.testng.TakeScreenShotOnAssertFail@59f99ea]" name="sampleTilteFailureTest" duration-ms="7577" started-at="2017-08-19T08:43:07Z" finished-at="2017-08-19T08:43:15Z">
          <exception class="java.lang.AssertionError">
            <message>
              <![CDATA[Assert1 expected [Twitter. It's what's happening.] but found [Facebook]]]>
            </message>
            <full-stacktrace>
              <![CDATA[java.lang.AssertionError: Assert1 expected [Twitter. It's what's happening.] but found [Facebook]
	at org.testng.Assert.fail(Assert.java:93)
	at org.testng.Assert.failNotEquals(Assert.java:512)
	at org.testng.Assert.assertEqualsImpl(Assert.java:134)
	at org.testng.Assert.assertEquals(Assert.java:115)
	at org.testng.Assert.assertEquals(Assert.java:189)
	at org.testng.asserts.Assertion$10.doAssert(Assertion.java:193)
	at org.testng.asserts.Assertion.executeAssert(Assertion.java:30)
	at org.testng.asserts.Assertion.doAssert(Assertion.java:15)
	at org.testng.asserts.Assertion.assertEquals(Assertion.java:190)
	at com.testingdocs.examples.testng.TakeScreenShotOnAssertFail.sampleTilteFailureTest(TakeScreenShotOnAssertFail.java:30)
	at sun.reflect.NativeMethodAccessorImpl.invoke0(Native Method)
	at sun.reflect.NativeMethodAccessorImpl.invoke(Unknown Source)
	at sun.reflect.DelegatingMethodAccessorImpl.invoke(Unknown Source)
	at java.lang.reflect.Method.invoke(Unknown Source)
	at org.testng.internal.MethodInvocationHelper.invokeMethod(MethodInvocationHelper.java:108)
	at org.testng.internal.Invoker.invokeMethod(Invoker.java:661)
	at org.testng.internal.Invoker.invokeTestMethod(Invoker.java:869)
	at org.testng.internal.Invoker.invokeTestMethods(Invoker.java:1193)
	at org.testng.internal.TestMethodWorker.invokeTestMethods(TestMethodWorker.java:126)
	at org.testng.internal.TestMethodWorker.run(TestMethodWorker.java:109)
	at org.testng.TestRunner.privateRun(TestRunner.java:744)
	at org.testng.TestRunner.run(TestRunner.java:602)
	at org.testng.SuiteRunner.runTest(SuiteRunner.java:380)
	at org.testng.SuiteRunner.runSequentially(SuiteRunner.java:375)
	at org.testng.SuiteRunner.privateRun(SuiteRunner.java:340)
	at org.testng.SuiteRunner.run(SuiteRunner.java:289)
	at org.testng.SuiteRunnerWorker.runSuite(SuiteRunnerWorker.java:52)
	at org.testng.SuiteRunnerWorker.run(SuiteRunnerWorker.java:86)
	at org.testng.TestNG.runSuitesSequentially(TestNG.java:1301)
	at org.testng.TestNG.runSuitesLocally(TestNG.java:1226)
	at org.testng.TestNG.runSuites(TestNG.java:1144)
	at org.testng.TestNG.run(TestNG.java:1115)
	at org.testng.remote.AbstractRemoteTestNG.run(AbstractRemoteTestNG.java:132)
	at org.testng.remote.RemoteTestNG.initAndRun(RemoteTestNG.java:230)
	at org.testng.remote.RemoteTestNG.main(RemoteTestNG.java:76)
]]>
            </full-stacktrace>
          </exception> <!-- java.lang.AssertionError -->
          <reporter-output>
          </reporter-output>
        </test-method> <!-- sampleTilteFailureTest -->
        <test-method status="PASS" signature="close()[pri:0, instance:com.testingdocs.examples.testng.TakeScreenShotOnAssertFail@59f99ea]" name="close" is-config="true" duration-ms="6424" started-at="2017-08-19T08:43:15Z" finished-at="2017-08-19T08:43:21Z">
          <reporter-output>
          </reporter-output>
        </test-method> <!-- close -->
      </class> <!-- com.testingdocs.examples.testng.TakeScreenShotOnAssertFail -->
    </test> <!-- Default test -->
  </suite> <!-- Default suite -->
</testng-results>
